Workbook

Sheet Assumptions
A1: Community Battery NPV Model — Assumptions
A2: Sources: CSIRO GenCost 2025, AER RORI 2025, Evoenergy TSS 2024
A4: Parameter | B4: Value | C4: Unit | D4: Source
A6: Battery Configuration
A7: Power rating | B7: 100 | C7: kW | D7: System specification
A8: Dispatch limit (base case) | B8: 80 | C8: kW | D8: Connection agreement
A9: Energy capacity — Scenario A | B9: 200 | C9: kWh | D9: Sensitivity parameter
A10: Energy capacity — Scenario B | B10: 400 | C10: kWh | D10: Sensitivity parameter
A12: Capital Costs
A13: Total installed cost (2hr, 200kWh) | B13: 580 | C13: A$/kWh | D13: GenCost 2025, 2hr, current policies
A14: Total installed cost (4hr, 400kWh) | B14: 406 | C14: A$/kWh | D14: GenCost 2025, 4hr, current policies
A15: Battery module cost (2hr) | B15: 309 | C15: A$/kWh | D15: GenCost 2025
A16: Battery module cost (4hr) | B16: 269 | C16: A$/kWh | D16: GenCost 2025
A17: BOP cost (2hr) | B17: 271 | C17: A$/kWh | D17: GenCost 2025
A18: BOP cost (4hr) | B18: 137 | C18: A$/kWh | D18: GenCost 2025
A19: Module cost 2037 (2hr, projected) | B19: 195 | C19: A$/kWh | D19: GenCost interpolated, current policies
A20: Module cost 2037 (4hr, projected) | B20: 168 | C20: A$/kWh | D20: GenCost interpolated, current policies
A21: Module cost 2037 (2hr, NZE post 2050) | B21: 157 | C21: A$/kWh | D21: GenCost interpolated, NZE post 2050
A22: Module cost 2037 (4hr, NZE post 2050) | B22: 106 | C22: A$/kWh | D22: GenCost interpolated, NZE post 2050
A24: Operating Costs
A25: O&M (% of capital per year) | B25: 0.015 | C25: % | D25: Industry estimate (1.5%)
A26: Degradation cost | B26: 0.02 | C26: A$/kWh | D26: Battery throughput cost
A28: Revenue — RL Dispatch (A$/day)
A29: RL revenue ±50kW / 200kWh | B29: 24.98 | C29: A$/day | D29: Q-learning result
A30: RL revenue ±50kW / 400kWh | B30: 35.9 | C30: A$/day | D30: Q-learning result
A31: RL revenue ±80kW / 200kWh | B31: 34.44 | C31: A$/day | D31: Q-learning result
A32: RL revenue ±80kW / 300kWh | B32: 42.5 | C32: A$/day | D32: Q-learning result
A33: RL revenue ±80kW / 400kWh | B33: 48.93 | C33: A$/day | D33: Q-learning result
A34: RL revenue ±100kW / 200kWh | B34: 36.31 | C34: A$/day | D34: Q-learning result
A35: RL revenue ±100kW / 400kWh | B35: 48.51 | C35: A$/day | D35: Q-learning result
A37: Financial Parameters
A38: Discount rate (nominal WACC) | B38: 0.0653 | C38: % | D38: AER RORI 2025 update
A39: Project lifetime | B39: 20 | C39: years | D39: Industry standard
A40: Battery module replacement year | B40: 12 | C40: year | D40: 70% capacity fade threshold
A41: Capacity fade rate | B41: 0.02 | C41: /year | D41: Linear ~2% per year
A42: Inflation rate | B42: 0.025 | C42: % | D42: RBA target
A44: Network Value
A45: LRMC import (residential) | B45: 125 | C45: A$/kW/yr | D45: Evoenergy TSS 2024
A46: LRMC export (residential) | B46: 23 | C46: A$/kW/yr | D46: Evoenergy TSS 2024
A47: Avoided augmentation (transformer) | B47: 45000 | C47: A$ | D47: Evoenergy estimate
...

Sheet NPV — 200kWh
A1: NPV Model: ±80kW / 200kWh Community Battery
A2: All values in A$ (2025 real terms)
B4: Value | C4: Unit | D4: Source
A5: Energy capacity | B5: 200 | C5: kWh
A6: Capital cost per kWh | B6: 580 | C6: A$/kWh | D6: GenCost 2025, 2hr
A7: Total capital cost | B7: =B5*B6 -> 116000 | C7: A$
A8: Daily RL revenue (±80kW) | B8: 34.44 | C8: A$/day | D8: Q-learning result, 0 violations
A9: O&M rate | B9: 0.015 | C9: % of cap/yr | D9: Industry estimate
A10: Discount rate | B10: 0.0653 | D10: AER RORI 2025
A11: Capacity fade | B11: 0.02 | C11: /year | D11: Linear
A12: Module replacement year | B12: 12
A13: Module cost per kWh | B13: 195 | C13: A$/kWh | D13: GenCost 2037 projected, current policies (was A$309 in 2025)
A14: LRMC export saving (kW) | B14: 50 | C14: kW | D14: Solar absorption
A15: LRMC export rate | B15: 23 | C15: A$/kW/yr | D15: Evoenergy TSS 2024
A16: Avoided augmentation PV | B16: =45000*(1-1/(1+B10)^10) -> 21094.753 | C16: A$
A18: Annual Cash Flow Projection
A19: Year | B19: Capacity Fade | C19: Adj Revenue/day | D19: Annual Revenue | E19: Export LRMC Saving | F19: O&M Cost | G19: Module Replacement | H19: Net Cash Flow | I19: Discount Factor | J19: Discounted CF | K19: Cumulative DCF
A20: 0 | G20: =-B7 -> -116000 | H20: =G20 -> -116000 | I20: 1 | J20: =H20*I20 -> -116000 | K20: =J20 -> -116000
A21: 1 | B21: =IF(A21<=$B$12, MAX(0.7, 1-$B$11*A21), MAX(0.7, 1-$B$11*(A21-$B$12))) -> 0.98 | C21: =$B$8*B21 -> 33.7512 | D21: =C21*365 -> 12319.188 | E21: =$B$14*$B$15 -> 1150 | F21: =-$B$9*$B$7 -> -1740 | G21: 0 | H21: =D21+E21+F21+G21 -> 11729.188 | I21: =1/(1+$B$10)^A21 -> 0.93870271 | J21: =H21*I21 -> 11010.221 | K21: =K20+J21 -> -104989.78
A22: 2 | B22: =IF(A22<=$B$12, MAX(0.7, 1-$B$11*A22), MAX(0.7, 1-$B$11*(A22-$B$12))) -> 0.96 | C22: =$B$8*B22 -> 33.0624 | D22: =C22*365 -> 12067.776 | E22: =$B$14*$B$15 -> 1150 | F22: =-$B$9*$B$7 -> -1740 | G22: 0 | H22: =D22+E22+F22+G22 -> 11477.776 | I22: =1/(1+$B$10)^A22 -> 0.88116278 | J22: =H22*I22 -> 10113.789 | K22: =K21+J22 -> -94875.99
A23: 3 | B23: =IF(A23<=$B$12, MAX(0.7, 1-$B$11*A23), MAX(0.7, 1-$B$11*(A23-$B$12))) -> 0.94 | C23: =$B$8*B23 -> 32.3736 | D23: =C23*365 -> 11816.364 | E23: =$B$14*$B$15 -> 1150 | F23: =-$B$9*$B$7 -> -1740 | G23: 0 | H23: =D23+E23+F23+G23 -> 11226.364 | I23: =1/(1+$B$10)^A23 -> 0.82714989 | J23: =H23*I23 -> 9285.8858 | K23: =K22+J23 -> -85590.105
A24: 4 | B24: =IF(A24<=$B$12, MAX(0.7, 1-$B$11*A24), MAX(0.7, 1-$B$11*(A24-$B$12))) -> 0.92 | C24: =$B$8*B24 -> 31.6848 | D24: =C24*365 -> 11564.952 | E24: =$B$14*$B$15 -> 1150 | F24: =-$B$9*$B$7 -> -1740 | G24: 0 | H24: =D24+E24+F24+G24 -> 10974.952 | I24: =1/(1+$B$10)^A24 -> 0.77644785 | J24: =H24*I24 -> 8521.4779 | K24: =K23+J24 -> -77068.627
A25: 5 | B25: =IF(A25<=$B$12, MAX(0.7, 1-$B$11*A25), MAX(0.7, 1-$B$11*(A25-$B$12))) -> 0.9 | C25: =$B$8*B25 -> 30.996 | D25: =C25*365 -> 11313.54 | E25: =$B$14*$B$15 -> 1150 | F25: =-$B$9*$B$7 -> -1740 | G25: 0 | H25: =D25+E25+F25+G25 -> 10723.54 | I25: =1/(1+$B$10)^A25 -> 0.7288537 | J25: =H25*I25 -> 7815.8918 | K25: =K24+J25 -> -69252.735
A26: 6 | B26: =IF(A26<=$B$12, MAX(0.7, 1-$B$11*A26), MAX(0.7, 1-$B$11*(A26-$B$12))) -> 0.88 | C26: =$B$8*B26 -> 30.3072 | D26: =C26*365 -> 11062.128 | E26: =$B$14*$B$15 -> 1150 | F26: =-$B$9*$B$7 -> -1740 | G26: 0 | H26: =D26+E26+F26+G26 -> 10472.128 | I26: =1/(1+$B$10)^A26 -> 0.68417695 | J26: =H26*I26 -> 7164.7886 | K26: =K25+J26 -> -62087.946
A27: 7 | B27: =IF(A27<=$B$12, MAX(0.7, 1-$B$11*A27), MAX(0.7, 1-$B$11*(A27-$B$12))) -> 0.86 | C27: =$B$8*B27 -> 29.6184 | D27: =C27*365 -> 10810.716 | E27: =$B$14*$B$15 -> 1150 | F27: =-$B$9*$B$7 -> -1740 | G27: 0 | H27: =D27+E27+F27+G27 -> 10220.716 | I27: =1/(1+$B$10)^A27 -> 0.64223876 | J27: =H27*I27 -> 6564.1399 | K27: =K26+J27 -> -55523.806
A28: 8 | B28: =IF(A28<=$B$12, MAX(0.7, 1-$B$11*A28), MAX(0.7, 1-$B$11*(A28-$B$12))) -> 0.84 | C28: =$B$8*B28 -> 28.9296 | D28: =C28*365 -> 10559.304 | E28: =$B$14*$B$15 -> 1150 | F28: =-$B$9*$B$7 -> -1740 | G28: 0 | H28: =D28+E28+F28+G28 -> 9969.304 | I28: =1/(1+$B$10)^A28 -> 0.60287126 | J28: =H28*I28 -> 6010.2069 | K28: =K27+J28 -> -49513.599
A29: 9 | B29: =IF(A29<=$B$12, MAX(0.7, 1-$B$11*A29), MAX(0.7, 1-$B$11*(A29-$B$12))) -> 0.82 | C29: =$B$8*B29 -> 28.2408 | D29: =C29*365 -> 10307.892 | E29: =$B$14*$B$15 -> 1150 | F29: =-$B$9*$B$7 -> -1740 | G29: 0 | H29: =D29+E29+F29+G29 -> 9717.892 | I29: =1/(1+$B$10)^A29 -> 0.56591689 | J29: =H29*I29 -> 5499.5192 | K29: =K28+J29 -> -44014.08
A30: 10 | B30: =IF(A30<=$B$12, MAX(0.7, 1-$B$11*A30), MAX(0.7, 1-$B$11*(A30-$B$12))) -> 0.8 | C30: =$B$8*B30 -> 27.552 | D30: =C30*365 -> 10056.48 | E30: =$B$14*$B$15 -> 1150 | F30: =-$B$9*$B$7 -> -1740 | G30: 0 | H30: =D30+E30+F30+G30 -> 9466.48 | I30: =1/(1+$B$10)^A30 -> 0.53122772 | J30: =H30*I30 -> 5028.8566 | K30: =K29+J30 -> -38985.224
A31: 11 | B31: =IF(A31<=$B$12, MAX(0.7, 1-$B$11*A31), MAX(0.7, 1-$B$11*(A31-$B$12))) -> 0.78 | C31: =$B$8*B31 -> 26.8632 | D31: =C31*365 -> 9805.068 | E31: =$B$14*$B$15 -> 1150 | F31: =-$B$9*$B$7 -> -1740 | G31: 0 | H31: =D31+E31+F31+G31 -> 9215.068 | I31: =1/(1+$B$10)^A31 -> 0.4986649 | J31: =H31*I31 -> 4595.231 | K31: =K30+J31 -> -34389.993
A32: 12 | B32: =IF(A32<=$B$12, MAX(0.7, 1-$B$11*A32), MAX(0.7, 1-$B$11*(A32-$B$12))) -> 0.76 | C32: =$B$8*B32 -> 26.1744 | D32: =C32*365 -> 9553.656 | E32: =$B$14*$B$15 -> 1150 | F32: =-$B$9*$B$7 -> -1740 | G32: =-$B$13*$B$5 -> -39000 | H32: =D32+E32+F32+G32 -> -30036.344 | I32: =1/(1+$B$10)^A32 -> 0.4680981 | J32: =H32*I32 -> -14059.955 | K32: =K31+J32 -> -48449.948
A33: 13 | B33: =IF(A33<=$B$12, MAX(0.7, 1-$B$11*A33), MAX(0.7, 1-$B$11*(A33-$B$12))) -> 0.98 | C33: =$B$8*B33 -> 33.7512 | D33: =C33*365 -> 12319.188 | E33: =$B$14*$B$15 -> 1150 | F33: =-$B$9*$B$7 -> -1740 | G33: 0 | H33: =D33+E33+F33+G33 -> 11729.188 | I33: =1/(1+$B$10)^A33 -> 0.43940495 | J33: =H33*I33 -> 5153.8633 | K33: =K32+J33 -> -43296.085
A34: 14 | B34: =IF(A34<=$B$12, MAX(0.7, 1-$B$11*A34), MAX(0.7, 1-$B$11*(A34-$B$12))) -> 0.96 | C34: =$B$8*B34 -> 33.0624 | D34: =C34*365 -> 12067.776 | E34: =$B$14*$B$15 -> 1150 | F34: =-$B$9*$B$7 -> -1740 | G34: 0 | H34: =D34+E34+F34+G34 -> 11477.776 | I34: =1/(1+$B$10)^A34 -> 0.41247062 | J34: =H34*I34 -> 4734.2454 | K34: =K33+J34 -> -38561.839
A35: 15 | B35: =IF(A35<=$B$12, MAX(0.7, 1-$B$11*A35), MAX(0.7, 1-$B$11*(A35-$B$12))) -> 0.94 | C35: =$B$8*B35 -> 32.3736 | D35: =C35*365 -> 11816.364 | E35: =$B$14*$B$15 -> 1150 | F35: =-$B$9*$B$7 -> -1740 | G35: 0 | H35: =D35+E35+F35+G35 -> 11226.364 | I35: =1/(1+$B$10)^A35 -> 0.38718729 | J35: =H35*I35 -> 4346.7055 | K35: =K34+J35 -> -34215.134
A36: 16 | B36: =IF(A36<=$B$12, MAX(0.7, 1-$B$11*A36), MAX(0.7, 1-$B$11*(A36-$B$12))) -> 0.92 | C36: =$B$8*B36 -> 31.6848 | D36: =C36*365 -> 11564.952 | E36: =$B$14*$B$15 -> 1150 | F36: =-$B$9*$B$7 -> -1740 | G36: 0 | H36: =D36+E36+F36+G36 -> 10974.952 | I36: =1/(1+$B$10)^A36 -> 0.36345376 | J36: =H36*I36 -> 3988.8876 | K36: =K35+J36 -> -30226.246
A37: 17 | B37: =IF(A37<=$B$12, MAX(0.7, 1-$B$11*A37), MAX(0.7, 1-$B$11*(A37-$B$12))) -> 0.9 | C37: =$B$8*B37 -> 30.996 | D37: =C37*365 -> 11313.54 | E37: =$B$14*$B$15 -> 1150 | F37: =-$B$9*$B$7 -> -1740 | G37: 0 | H37: =D37+E37+F37+G37 -> 10723.54 | I37: =1/(1+$B$10)^A37 -> 0.34117503 | J37: =H37*I37 -> 3658.6041 | K37: =K36+J37 -> -26567.642
A38: 18 | B38: =IF(A38<=$B$12, MAX(0.7, 1-$B$11*A38), MAX(0.7, 1-$B$11*(A38-$B$12))) -> 0.88 | C38: =$B$8*B38 -> 30.3072 | D38: =C38*365 -> 11062.128 | E38: =$B$14*$B$15 -> 1150 | F38: =-$B$9*$B$7 -> -1740 | G38: 0 | H38: =D38+E38+F38+G38 -> 10472.128 | I38: =1/(1+$B$10)^A38 -> 0.32026193 | J38: =H38*I38 -> 3353.8239 | K38: =K37+J38 -> -23213.818
A39: 19 | B39: =IF(A39<=$B$12, MAX(0.7, 1-$B$11*A39), MAX(0.7, 1-$B$11*(A39-$B$12))) -> 0.86 | C39: =$B$8*B39 -> 29.6184 | D39: =C39*365 -> 10810.716 | E39: =$B$14*$B$15 -> 1150 | F39: =-$B$9*$B$7 -> -1740 | G39: 0 | H39: =D39+E39+F39+G39 -> 10220.716 | I39: =1/(1+$B$10)^A39 -> 0.30063074 | J39: =H39*I39 -> 3072.6614 | K39: =K38+J39 -> -20141.157
A40: 20 | B40: =IF(A40<=$B$12, MAX(0.7, 1-$B$11*A40), MAX(0.7, 1-$B$11*(A40-$B$12))) -> 0.84 | C40: =$B$8*B40 -> 28.9296 | D40: =C40*365 -> 10559.304 | E40: =$B$14*$B$15 -> 1150 | F40: =-$B$9*$B$7 -> -1740 | G40: 0 | H40: =D40+E40+F40+G40 -> 9969.304 | I40: =1/(1+$B$10)^A40 -> 0.28220289 | J40: =H40*I40 -> 2813.3664 | K40: =K39+J40 -> -17327.79
A42: Summary Metrics
A43: Total capital cost | B43: =B7 -> 116000
...

Sheet NPV — 400kWh
A1: NPV Model: ±80kW / 400kWh Community Battery
A2: All values in A$ (2025 real terms)
B4: Value | C4: Unit | D4: Source
A5: Energy capacity | B5: 400 | C5: kWh
A6: Capital cost per kWh | B6: 406 | C6: A$/kWh | D6: GenCost 2025, 4hr
A7: Total capital cost | B7: =B5*B6 -> 162400 | C7: A$
A8: Daily RL revenue (±80kW) | B8: 48.93 | C8: A$/day | D8: Q-learning result, 0 violations
A9: O&M rate | B9: 0.015 | C9: % of cap/yr | D9: Industry estimate
A10: Discount rate | B10: 0.0653 | D10: AER RORI 2025
A11: Capacity fade | B11: 0.02 | C11: /year | D11: Linear
A12: Module replacement year | B12: 12
A13: Module cost per kWh | B13: 168 | C13: A$/kWh | D13: GenCost 2037 projected, current policies (was A$269 in 2025)
A14: LRMC export saving (kW) | B14: 50 | C14: kW | D14: Solar absorption
A15: LRMC export rate | B15: 23 | C15: A$/kW/yr | D15: Evoenergy TSS 2024
A16: Avoided augmentation PV | B16: =45000*(1-1/(1+B10)^10) -> 21094.753 | C16: A$
A18: Annual Cash Flow Projection
A19: Year | B19: Capacity Fade | C19: Adj Revenue/day | D19: Annual Revenue | E19: Export LRMC Saving | F19: O&M Cost | G19: Module Replacement | H19: Net Cash Flow | I19: Discount Factor | J19: Discounted CF | K19: Cumulative DCF
A20: 0 | G20: =-B7 -> -162400 | H20: =G20 -> -162400 | I20: 1 | J20: =H20*I20 -> -162400 | K20: =J20 -> -162400
A21: 1 | B21: =IF(A21<=$B$12, MAX(0.7, 1-$B$11*A21), MAX(0.7, 1-$B$11*(A21-$B$12))) -> 0.98 | C21: =$B$8*B21 -> 47.9514 | D21: =C21*365 -> 17502.261 | E21: =$B$14*$B$15 -> 1150 | F21: =-$B$9*$B$7 -> -2436 | G21: 0 | H21: =D21+E21+F21+G21 -> 16216.261 | I21: =1/(1+$B$10)^A21 -> 0.93870271 | J21: =H21*I21 -> 15222.248 | K21: =K20+J21 -> -147177.75
A22: 2 | B22: =IF(A22<=$B$12, MAX(0.7, 1-$B$11*A22), MAX(0.7, 1-$B$11*(A22-$B$12))) -> 0.96 | C22: =$B$8*B22 -> 46.9728 | D22: =C22*365 -> 17145.072 | E22: =$B$14*$B$15 -> 1150 | F22: =-$B$9*$B$7 -> -2436 | G22: 0 | H22: =D22+E22+F22+G22 -> 15859.072 | I22: =1/(1+$B$10)^A22 -> 0.88116278 | J22: =H22*I22 -> 13974.424 | K22: =K21+J22 -> -133203.33
A23: 3 | B23: =IF(A23<=$B$12, MAX(0.7, 1-$B$11*A23), MAX(0.7, 1-$B$11*(A23-$B$12))) -> 0.94 | C23: =$B$8*B23 -> 45.9942 | D23: =C23*365 -> 16787.883 | E23: =$B$14*$B$15 -> 1150 | F23: =-$B$9*$B$7 -> -2436 | G23: 0 | H23: =D23+E23+F23+G23 -> 15501.883 | I23: =1/(1+$B$10)^A23 -> 0.82714989 | J23: =H23*I23 -> 12822.381 | K23: =K22+J23 -> -120380.95
A24: 4 | B24: =IF(A24<=$B$12, MAX(0.7, 1-$B$11*A24), MAX(0.7, 1-$B$11*(A24-$B$12))) -> 0.92 | C24: =$B$8*B24 -> 45.0156 | D24: =C24*365 -> 16430.694 | E24: =$B$14*$B$15 -> 1150 | F24: =-$B$9*$B$7 -> -2436 | G24: 0 | H24: =D24+E24+F24+G24 -> 15144.694 | I24: =1/(1+$B$10)^A24 -> 0.77644785 | J24: =H24*I24 -> 11759.065 | K24: =K23+J24 -> -108621.88
A25: 5 | B25: =IF(A25<=$B$12, MAX(0.7, 1-$B$11*A25), MAX(0.7, 1-$B$11*(A25-$B$12))) -> 0.9 | C25: =$B$8*B25 -> 44.037 | D25: =C25*365 -> 16073.505 | E25: =$B$14*$B$15 -> 1150 | F25: =-$B$9*$B$7 -> -2436 | G25: 0 | H25: =D25+E25+F25+G25 -> 14787.505 | I25: =1/(1+$B$10)^A25 -> 0.7288537 | J25: =H25*I25 -> 10777.928 | K25: =K24+J25 -> -97843.954
A26: 6 | B26: =IF(A26<=$B$12, MAX(0.7, 1-$B$11*A26), MAX(0.7, 1-$B$11*(A26-$B$12))) -> 0.88 | C26: =$B$8*B26 -> 43.0584 | D26: =C26*365 -> 15716.316 | E26: =$B$14*$B$15 -> 1150 | F26: =-$B$9*$B$7 -> -2436 | G26: 0 | H26: =D26+E26+F26+G26 -> 14430.316 | I26: =1/(1+$B$10)^A26 -> 0.68417695 | J26: =H26*I26 -> 9872.8896 | K26: =K25+J26 -> -87971.064
A27: 7 | B27: =IF(A27<=$B$12, MAX(0.7, 1-$B$11*A27), MAX(0.7, 1-$B$11*(A27-$B$12))) -> 0.86 | C27: =$B$8*B27 -> 42.0798 | D27: =C27*365 -> 15359.127 | E27: =$B$14*$B$15 -> 1150 | F27: =-$B$9*$B$7 -> -2436 | G27: 0 | H27: =D27+E27+F27+G27 -> 14073.127 | I27: =1/(1+$B$10)^A27 -> 0.64223876 | J27: =H27*I27 -> 9038.3076 | K27: =K26+J27 -> -78932.757
A28: 8 | B28: =IF(A28<=$B$12, MAX(0.7, 1-$B$11*A28), MAX(0.7, 1-$B$11*(A28-$B$12))) -> 0.84 | C28: =$B$8*B28 -> 41.1012 | D28: =C28*365 -> 15001.938 | E28: =$B$14*$B$15 -> 1150 | F28: =-$B$9*$B$7 -> -2436 | G28: 0 | H28: =D28+E28+F28+G28 -> 13715.938 | I28: =1/(1+$B$10)^A28 -> 0.60287126 | J28: =H28*I28 -> 8268.9449 | K28: =K27+J28 -> -70663.812
A29: 9 | B29: =IF(A29<=$B$12, MAX(0.7, 1-$B$11*A29), MAX(0.7, 1-$B$11*(A29-$B$12))) -> 0.82 | C29: =$B$8*B29 -> 40.1226 | D29: =C29*365 -> 14644.749 | E29: =$B$14*$B$15 -> 1150 | F29: =-$B$9*$B$7 -> -2436 | G29: 0 | H29: =D29+E29+F29+G29 -> 13358.749 | I29: =1/(1+$B$10)^A29 -> 0.56591689 | J29: =H29*I29 -> 7559.9417 | K29: =K28+J29 -> -63103.87
A30: 10 | B30: =IF(A30<=$B$12, MAX(0.7, 1-$B$11*A30), MAX(0.7, 1-$B$11*(A30-$B$12))) -> 0.8 | C30: =$B$8*B30 -> 39.144 | D30: =C30*365 -> 14287.56 | E30: =$B$14*$B$15 -> 1150 | F30: =-$B$9*$B$7 -> -2436 | G30: 0 | H30: =D30+E30+F30+G30 -> 13001.56 | I30: =1/(1+$B$10)^A30 -> 0.53122772 | J30: =H30*I30 -> 6906.7891 | K30: =K29+J30 -> -56197.081
A31: 11 | B31: =IF(A31<=$B$12, MAX(0.7, 1-$B$11*A31), MAX(0.7, 1-$B$11*(A31-$B$12))) -> 0.78 | C31: =$B$8*B31 -> 38.1654 | D31: =C31*365 -> 13930.371 | E31: =$B$14*$B$15 -> 1150 | F31: =-$B$9*$B$7 -> -2436 | G31: 0 | H31: =D31+E31+F31+G31 -> 12644.371 | I31: =1/(1+$B$10)^A31 -> 0.4986649 | J31: =H31*I31 -> 6305.304 | K31: =K30+J31 -> -49891.777
A32: 12 | B32: =IF(A32<=$B$12, MAX(0.7, 1-$B$11*A32), MAX(0.7, 1-$B$11*(A32-$B$12))) -> 0.76 | C32: =$B$8*B32 -> 37.1868 | D32: =C32*365 -> 13573.182 | E32: =$B$14*$B$15 -> 1150 | F32: =-$B$9*$B$7 -> -2436 | G32: =-$B$13*$B$5 -> -67200 | H32: =D32+E32+F32+G32 -> -54912.818 | I32: =1/(1+$B$10)^A32 -> 0.4680981 | J32: =H32*I32 -> -25704.586 | K32: =K31+J32 -> -75596.363
A33: 13 | B33: =IF(A33<=$B$12, MAX(0.7, 1-$B$11*A33), MAX(0.7, 1-$B$11*(A33-$B$12))) -> 0.98 | C33: =$B$8*B33 -> 47.9514 | D33: =C33*365 -> 17502.261 | E33: =$B$14*$B$15 -> 1150 | F33: =-$B$9*$B$7 -> -2436 | G33: 0 | H33: =D33+E33+F33+G33 -> 16216.261 | I33: =1/(1+$B$10)^A33 -> 0.43940495 | J33: =H33*I33 -> 7125.5054 | K33: =K32+J33 -> -68470.857
A34: 14 | B34: =IF(A34<=$B$12, MAX(0.7, 1-$B$11*A34), MAX(0.7, 1-$B$11*(A34-$B$12))) -> 0.96 | C34: =$B$8*B34 -> 46.9728 | D34: =C34*365 -> 17145.072 | E34: =$B$14*$B$15 -> 1150 | F34: =-$B$9*$B$7 -> -2436 | G34: 0 | H34: =D34+E34+F34+G34 -> 15859.072 | I34: =1/(1+$B$10)^A34 -> 0.41247062 | J34: =H34*I34 -> 6541.4013 | K34: =K33+J34 -> -61929.456
A35: 15 | B35: =IF(A35<=$B$12, MAX(0.7, 1-$B$11*A35), MAX(0.7, 1-$B$11*(A35-$B$12))) -> 0.94 | C35: =$B$8*B35 -> 45.9942 | D35: =C35*365 -> 16787.883 | E35: =$B$14*$B$15 -> 1150 | F35: =-$B$9*$B$7 -> -2436 | G35: 0 | H35: =D35+E35+F35+G35 -> 15501.883 | I35: =1/(1+$B$10)^A35 -> 0.38718729 | J35: =H35*I35 -> 6002.1321 | K35: =K34+J35 -> -55927.324
A36: 16 | B36: =IF(A36<=$B$12, MAX(0.7, 1-$B$11*A36), MAX(0.7, 1-$B$11*(A36-$B$12))) -> 0.92 | C36: =$B$8*B36 -> 45.0156 | D36: =C36*365 -> 16430.694 | E36: =$B$14*$B$15 -> 1150 | F36: =-$B$9*$B$7 -> -2436 | G36: 0 | H36: =D36+E36+F36+G36 -> 15144.694 | I36: =1/(1+$B$10)^A36 -> 0.36345376 | J36: =H36*I36 -> 5504.396 | K36: =K35+J36 -> -50422.928
A37: 17 | B37: =IF(A37<=$B$12, MAX(0.7, 1-$B$11*A37), MAX(0.7, 1-$B$11*(A37-$B$12))) -> 0.9 | C37: =$B$8*B37 -> 44.037 | D37: =C37*365 -> 16073.505 | E37: =$B$14*$B$15 -> 1150 | F37: =-$B$9*$B$7 -> -2436 | G37: 0 | H37: =D37+E37+F37+G37 -> 14787.505 | I37: =1/(1+$B$10)^A37 -> 0.34117503 | J37: =H37*I37 -> 5045.1275 | K37: =K36+J37 -> -45377.8
A38: 18 | B38: =IF(A38<=$B$12, MAX(0.7, 1-$B$11*A38), MAX(0.7, 1-$B$11*(A38-$B$12))) -> 0.88 | C38: =$B$8*B38 -> 43.0584 | D38: =C38*365 -> 15716.316 | E38: =$B$14*$B$15 -> 1150 | F38: =-$B$9*$B$7 -> -2436 | G38: 0 | H38: =D38+E38+F38+G38 -> 14430.316 | I38: =1/(1+$B$10)^A38 -> 0.32026193 | J38: =H38*I38 -> 4621.4808 | K38: =K37+J38 -> -40756.32
A39: 19 | B39: =IF(A39<=$B$12, MAX(0.7, 1-$B$11*A39), MAX(0.7, 1-$B$11*(A39-$B$12))) -> 0.86 | C39: =$B$8*B39 -> 42.0798 | D39: =C39*365 -> 15359.127 | E39: =$B$14*$B$15 -> 1150 | F39: =-$B$9*$B$7 -> -2436 | G39: 0 | H39: =D39+E39+F39+G39 -> 14073.127 | I39: =1/(1+$B$10)^A39 -> 0.30063074 | J39: =H39*I39 -> 4230.8146 | K39: =K38+J39 -> -36525.505
A40: 20 | B40: =IF(A40<=$B$12, MAX(0.7, 1-$B$11*A40), MAX(0.7, 1-$B$11*(A40-$B$12))) -> 0.84 | C40: =$B$8*B40 -> 41.1012 | D40: =C40*365 -> 15001.938 | E40: =$B$14*$B$15 -> 1150 | F40: =-$B$9*$B$7 -> -2436 | G40: 0 | H40: =D40+E40+F40+G40 -> 13715.938 | I40: =1/(1+$B$10)^A40 -> 0.28220289 | J40: =H40*I40 -> 3870.6774 | K40: =K39+J40 -> -32654.828
A42: Summary Metrics
A43: Total capital cost | B43: =B7 -> 162400
...

Sheet Comparison
A1: Investment Comparison: 200kWh vs 400kWh
A3: Metric | B3: 200 kWh | C3: 400 kWh | D3: Difference
A4: Capital cost | B4: ='NPV — 200kWh'!B7 -> 116000 | C4: ='NPV — 400kWh'!B7 -> 162400 | D4: =C4-B4 -> 46400
A5: Daily RL revenue (±80kW) | B5: ='NPV — 200kWh'!B8 -> 34.44 | C5: ='NPV — 400kWh'!B8 -> 48.93 | D5: =C5-B5 -> 14.49
A6: Year 1 annual revenue | B6: ='NPV — 200kWh'!D21 -> 12319.188 | C6: ='NPV — 400kWh'!D21 -> 17502.261 | D6: =C6-B6 -> 5183.073
A7: Year 1 net cash flow | B7: ='NPV — 200kWh'!H21 -> 11729.188 | C7: ='NPV — 400kWh'!H21 -> 16216.261 | D7: =C7-B7 -> 4487.073
A8: Simple payback (years) | B8: ='NPV — 200kWh'!B46 -> 9.416205 | C8: ='NPV — 400kWh'!B46 -> 9.2788012 | D8: =C8-B8 -> -0.13740385
A9: NPV (20 years) | B9: ='NPV — 200kWh'!B44 -> -17327.79 | C9: ='NPV — 400kWh'!B44 -> -32654.828 | D9: =C9-B9 -> -15327.037
A10: NPV + avoided augmentation | B10: ='NPV — 200kWh'!B45 -> 3766.9621 | C10: ='NPV — 400kWh'!B45 -> -11560.075 | D10: =C10-B10 -> -15327.037
A11: RL violations | B11: 0 | C11: 0 | D11: =C11-B11 -> 0
A12: DP violations (for comparison) | B12: 6 | C12: 3 | D12: =C12-B12 -> -3
A15: Key Insight:
A16: The 400 kWh battery costs 40% more but earns 42% more revenue per year.
A17: Both achieve 0 violations with RL dispatch at ±80kW.
A18: The marginal cost of the extra 200 kWh is only A$46,400 (A$406-A$580 per kWh effect).
